Workbook

Sheet GDP_By_Main_Economic_Activity
A1: Date | B1: Quarter | C1: Oil Activities | D1: Non-Oil Activities | E1: Government Activities | F1: Gross Value Added | G1: Net Taxes on Products | H1: Gross Domestic Product
A2: 42825 | B2: 2017Q1 | C2: 323387 | D2: 427664 | E2: 141861 | F2: 889235 | G2: 41728 | H2: 932702
A3: 42916 | B3: 2017Q2 | C3: 327933 | D3: 429552 | E3: 129052 | F3: 878557 | G3: 46796 | H3: 922635
A4: 43008 | B4: 2017Q3 | C4: 332904 | D4: 443768 | E4: 122371 | F4: 890649 | G4: 39464 | H4: 933711
A5: 43100 | B5: 2017Q4 | C5: 329685 | D5: 447054 | E5: 160031 | F5: 938914 | G5: 45812 | H5: 985165
A6: 43190 | B6: 2018Q1 | C6: 324708 | D6: 441322 | E6: 148584 | F6: 913445 | G6: 42822 | H6: 958113
A7: 43281 | B7: 2018Q2 | C7: 331130 | D7: 446211 | E7: 139218 | F7: 912852 | G7: 46922 | H7: 958245
A8: 43373 | B8: 2018Q3 | C8: 344068 | D8: 458359 | E8: 123729 | F8: 918207 | G8: 40861 | H8: 962710
A9: 43465 | B9: 2018Q4 | C9: 351618 | D9: 458356 | E9: 163205 | F9: 969385 | G9: 46254 | H9: 1016937
A10: 43555 | B10: 2019Q1 | C10: 327142 | D10: 461734 | E10: 150640 | F10: 937130 | G10: 48676 | H10: 985357
A11: 43646 | B11: 2019Q2 | C11: 320037 | D11: 467902 | E11: 140746 | F11: 925793 | G11: 49877 | H11: 974442
A12: 43738 | B12: 2019Q3 | C12: 320876 | D12: 481536 | E12: 129495 | F12: 927830 | G12: 49855 | H12: 976512
A13: 43830 | B13: 2019Q4 | C13: 330154 | D13: 480815 | E13: 163790 | F13: 973887 | G13: 50645 | H13: 1024040
... A37: 46022 | B37: 2025Q4 | C37: 343238 | D37: 686497 | E37: 178064 | F37: 1206974 | G37: 65609 | H37: 1272528

Sheet balance_of_payments
A1: Date | B1: Exports | C1: Imports
A2: 40268 | B2: 218109000 | C2: 82644500
A3: 40359 | B3: 229396000 | C3: 92419900
A4: 40451 | B4: 226448000 | C4: 90270400
A5: 40543 | B5: 267832000 | C5: 96024600
A6: 40633 | B6: 304907000 | C6: 98265100
A7: 40724 | B7: 342634000 | C7: 113338800
A8: 40816 | B8: 352534000 | C8: 115825500
A9: 40908 | B9: 367544936 | C9: 117488700
A10: 40999 | B10: 386790000 | C10: 123055000
A11: 41090 | B11: 367846000 | C11: 135582310
A12: 41182 | B12: 346435000 | C12: 133421390
A13: 41274 | B13: 355315000 | C13: 133853400
... A65: 46022 | B65: 300397074 | C65: 222915189

Sheet Government_Revenues
A1: Date | B1: Quarter | C1: Total Revenue | D1: Oil Revenue | E1: Non Oil Revenues | F1: Taxes Revenues | G1: Income Taxes | H1: VAT | I1: INT Taxes | J1: Other Taxes | K1: Other Revenues
A2: 42825 | B2: 2017Q1 | C2: 144100 | D2: 115100 | E2: 29000 | F2: 21900 | G2: 2100 | H2: 10400 | I2: 5300 | J2: 4100 | K2: 7100
A3: 42916 | B3: 2017Q2 | C3: 163900 | D3: 101000 | E3: 62900 | F3: 26700 | G3: 3500 | H3: 11200 | I3: 5800 | J3: 6200 | K3: 36200
A4: 43008 | B4: 2017Q3 | C4: 142100 | D4: 94300 | E4: 47800 | F4: 25300 | G4: 2800 | H4: 12100 | I4: 4900 | J4: 5500 | K4: 22500
A5: 43100 | B5: 2017Q4 | C5: 241500 | D5: 129500 | E5: 112000 | F5: 36500 | G5: 5100 | H5: 13100 | I5: 5400 | J5: 12900 | K5: 75500
A6: 43190 | B6: 2018Q1 | C6: 166300 | D6: 113900 | E6: 52400 | F6: 35900 | G6: 3200 | H6: 24300 | I6: 3800 | J6: 4600 | K6: 16500
A7: 43281 | B7: 2018Q2 | C7: 273600 | D7: 184200 | E7: 89400 | F7: 48400 | G7: 4400 | H7: 29500 | I7: 4300 | J7: 10200 | K7: 41000
A8: 43373 | B8: 2018Q3 | C8: 223300 | D8: 154000 | E8: 69300 | F8: 43900 | G8: 3900 | H8: 30100 | I8: 4100 | J8: 5800 | K8: 25400
A9: 43465 | B9: 2018Q4 | C9: 252000 | D9: 158000 | E9: 94000 | F9: 58300 | G9: 5200 | H9: 34200 | I9: 4400 | J9: 14500 | K9: 35700
A10: 43555 | B10: 2019Q1 | C10: 245400 | D10: 169100 | E10: 76300 | F10: 51900 | G10: 3500 | H10: 39100 | I10: 4200 | J10: 5100 | K10: 24400
A11: 43646 | B11: 2019Q2 | C11: 260700 | D11: 174400 | E11: 86300 | F11: 60300 | G11: 4800 | H11: 38600 | I11: 4500 | J11: 12400 | K11: 26000
A12: 43738 | B12: 2019Q3 | C12: 171500 | D12: 131800 | E12: 62100 | F12: 50900 | G12: 4100 | H12: 37400 | I12: 4100 | J12: 5300 | K12: 11200
A13: 43830 | B13: 2019Q4 | C13: 239100 | D13: 118800 | E13: 120300 | F13: 70500 | G13: 5700 | H13: 44500 | I13: 4700 | J13: 15600 | K13: 49800
... A37: 46022 | B37: 2025Q4 | C37: 348900 | D37: 154185 | E37: 122558 | F37: 89774 | G37: 6969 | H37: 73502 | I37: 6712 | J37: 2591 | K37: 32784

Sheet Government_Expenditures
A1: Date | B1: Quarter | C1: Total Exp | D1: Compensation | E1: Goods/Services | F1: Financing | G1: Subsidies | H1: Grants | I1: Social Benefits | J1: Other Expenses | K1: CAPEX
A2: 42825 | B2: 2017Q1 | C2: 170300 | D2: 90400 | E2: 18200 | F2: 900 | G2: 1200 | H2: 120 | I2: 13400 | J2: 36780 | K2: 9300
A3: 42916 | B3: 2017Q2 | C3: 210400 | D3: 102100 | E3: 25600 | F3: 1400 | G3: 1800 | H3: 1500 | I3: 15600 | J3: 27700 | K3: 34700
A4: 43008 | B4: 2017Q3 | C4: 190900 | D4: 100500 | E4: 22100 | F4: 1100 | G4: 1500 | H4: 700 | I4: 14800 | J4: 25700 | K4: 24500
A5: 43100 | B5: 2017Q4 | C5: 356400 | D5: 114200 | E5: 65300 | F5: 2700 | G5: 3900 | H5: 9100 | I5: 18500 | J5: 41700 | K5: 101000
A6: 43190 | B6: 2018Q1 | C6: 200600 | D6: 106700 | E6: 19800 | F6: 1200 | G6: 2100 | H6: 250 | I6: 19300 | J6: 25950 | K6: 25300
A7: 43281 | B7: 2018Q2 | C7: 281000 | D7: 120400 | E7: 45600 | F7: 1900 | G7: 3400 | H7: 500 | I7: 25400 | J7: 29900 | K7: 53900
A8: 43373 | B8: 2018Q3 | C8: 230500 | D8: 115200 | E8: 30100 | F8: 1500 | G8: 2800 | H8: 2100 | I8: 19400 | J8: 13100 | K8: 46300
A9: 43465 | B9: 2018Q4 | C9: 318000 | D9: 126100 | E9: 46800 | F9: 2100 | G9: 4200 | H9: 2450 | I9: 26500 | J9: 39850 | K9: 70000
A10: 43555 | B10: 2019Q1 | C10: 217600 | D10: 121500 | E10: 22400 | F10: 1800 | G10: 3100 | H10: 300 | I10: 18900 | J10: 27900 | K10: 21700
A11: 43646 | B11: 2019Q2 | C11: 267200 | D11: 125400 | E11: 43200 | F11: 2400 | G11: 5200 | H11: 1000 | I11: 22100 | J11: 19100 | K11: 48800
A12: 43738 | B12: 2019Q3 | C12: 203600 | D12: 118600 | E12: 25100 | F12: 2100 | G12: 4500 | H12: 600 | I12: 17400 | J12: 16700 | K12: 18600
A13: 43830 | B13: 2019Q4 | C13: 371400 | D13: 129500 | E13: 85400 | F13: 3400 | G13: 8200 | H13: 5400 | I13: 25600 | J13: 31200 | K13: 82700
... A36: 45930 | B36: 2025Q3 | C36: 358397 | D36: 64633.209 | E36: 12387.833 | F36: 6492.3327 | G36: 273.782 | H36: 30474.01 | I36: 34180.298 | J36: 27785.705 | K36: 39909.474
A37: 46022 | C37: 371589.13 | D37: 94156.57 | E37: 14933.627 | F37: 7941.5471 | G37: 4177.336 | H37: 13130.763 | I37: 41874.101 | J37: 50905.632 | K37: 27785.705
A38: 46112 | K38: 28086.515
A39: 46203
A40: 46295
A41: 46387
A42: 46112 | K42: 28086.515
A43: 46203
A44: 46295
A45: 46387 | B45: 2025Q4
A46: 46112 | K46: 28086.515
A47: 46203
A48: 46295
A49: 46387 | B49: 2025Q4

Sheet Purchasing_Managers_Index
A1: Date | B1: Quarter | C1: PMI
A2: 42825 | B2: 2017Q1 | C2: 56.7
A3: 42916 | B3: 2017Q2 | C3: 55.4
A4: 43008 | B4: 2017Q3 | C4: 55.7
A5: 43100 | B5: 2017Q4 | C5: 56.8
A6: 43190 | B6: 2018Q1 | C6: 53
A7: 43281 | B7: 2018Q2 | C7: 53.8
A8: 43373 | B8: 2018Q3 | C8: 54.8
A9: 43465 | B9: 2018Q4 | C9: 55.9
A10: 43555 | B10: 2019Q1 | C10: 56.5
A11: 43646 | B11: 2019Q2 | C11: 57.2
A12: 43738 | B12: 2019Q3 | C12: 57
A13: 43830 | B13: 2019Q4 | C13: 57.7
... A37: 46022 | B37: 2025Q4 | C37: 58.7
A38: 46112 | C38: 56.2

Sheet Point_of_Sales_Transactions
A1: Date | B1: Quarter | C1: Value
A2: 42825 | B2: 2017Q1 | C2: 15358633
A3: 42916 | B3: 2017Q2 | C3: 17061200
A4: 43008 | B4: 2017Q3 | C4: 16125500
A5: 43100 | B5: 2017Q4 | C5: 17518700
A6: 43190 | B6: 2018Q1 | C6: 18472100
A7: 43281 | B7: 2018Q2 | C7: 20163900
A8: 43373 | B8: 2018Q3 | C8: 20220500
A9: 43465 | B9: 2018Q4 | C9: 21362167
A10: 43555 | B10: 2019Q1 | C10: 23405433
A11: 43646 | B11: 2019Q2 | C11: 25805533
A12: 43738 | B12: 2019Q3 | C12: 25850400
A13: 43830 | B13: 2019Q4 | C13: 27472033
... A37: 46022 | B37: 2025Q4 | C37: 69266667
A38: 46112 | C38: 63770236

Sheet Crude_Oil
A1: Date | B1: Quarter | C1: Production | D1: Price
A2: 42825 | B2: 2017Q1 | C2: 9898 | D2: 53.883333
A3: 42916 | B3: 2017Q2 | C3: 9948 | D3: 50.1
A4: 43008 | B4: 2017Q3 | C4: 10005 | D4: 52.11
A5: 43100 | B5: 2017Q4 | C5: 9992.6667 | D5: 61.53
A6: 43190 | B6: 2018Q1 | C6: 9955.3333 | D6: 66.806667
A7: 43281 | B7: 2018Q2 | C7: 10116.333 | D7: 74.383333
A8: 43373 | B8: 2018Q3 | C8: 10437 | D8: 75.24
A9: 43465 | B9: 2018Q4 | C9: 10757 | D9: 67.906667
A10: 43555 | B10: 2019Q1 | C10: 10055.667 | D10: 63.196667
A11: 43646 | B11: 2019Q2 | C11: 9731.3333 | D11: 68.543333
A12: 43738 | B12: 2019Q3 | C12: 9528 | D12: 62.083333
A13: 43830 | B13: 2019Q4 | C13: 9824 | D13: 63.41
... A37: 46022 | B37: 2025Q4 | C37: 9716.6667 | D37: 59.196667
A38: 46112 | C38: 10098.667 | D38: 74.153333

Sheet Money_Supply
A1: Date | B1: Quarter | C1: M3
A2: 42825 | B2: 2017Q1 | C2: 1779430.4
A3: 42916 | B3: 2017Q2 | C3: 1803423
A4: 43008 | B4: 2017Q3 | C4: 1804225.9
A5: 43100 | B5: 2017Q4 | C5: 1790167.3
A6: 43190 | B6: 2018Q1 | C6: 1802989.5
A7: 43281 | B7: 2018Q2 | C7: 1802537.1
A8: 43373 | B8: 2018Q3 | C8: 1815545.4
A9: 43465 | B9: 2018Q4 | C9: 1829630.8
A10: 43555 | B10: 2019Q1 | C10: 1829866.9
A11: 43646 | B11: 2019Q2 | C11: 1871915.9
A12: 43738 | B12: 2019Q3 | C12: 1885259
A13: 43830 | B13: 2019Q4 | C13: 1934567.8
... A38: 46112 | B38: 2026Q1 | C38: 3297055.4

Sheet International_Trade
A1: Date | B1: Quarter | C1: Exports | D1: Imports | E1: Trade Volume | F1: Trade Balance
A2: 42825 | B2: 2017Q1 | C2: 207374 | D2: 125720 | E2: 333094 | F2: 81653
A3: 42916 | B3: 2017Q2 | C3: 189728 | D3: 126710 | E3: 316439 | F3: 63018
A4: 43008 | B4: 2017Q3 | C4: 196288 | D4: 123854 | E4: 320142 | F4: 72435
A5: 43100 | B5: 2017Q4 | C5: 238491 | D5: 128162 | E5: 366653 | F5: 110328
A6: 43190 | B6: 2018Q1 | C6: 244235 | D6: 126056 | E6: 370291 | F6: 118179
A7: 43281 | B7: 2018Q2 | C7: 281094 | D7: 133020 | E7: 414114 | F7: 148074
A8: 43373 | B8: 2018Q3 | C8: 288432 | D8: 128021 | E8: 416453 | F8: 160410
A9: 43465 | B9: 2018Q4 | C9: 290140 | D9: 126896 | E9: 417036 | F9: 163244
A10: 43555 | B10: 2019Q1 | C10: 249087 | D10: 132192 | E10: 381279 | F10: 116895
A11: 43646 | B11: 2019Q2 | C11: 252617 | D11: 151819 | E11: 404436 | F11: 100798
A12: 43738 | B12: 2019Q3 | C12: 235874 | D12: 145451 | E12: 381325 | F12: 90422
A13: 43830 | B13: 2019Q4 | C13: 243434 | D13: 144900 | E13: 388334 | F13: 98535
... A37: 46022 | B37: 2025Q4 | C37: 300128 | D37: 247684 | E37: 547811 | F37: 52444

Sheet Consumer_Price_Index
A1: Date; | B1: Quarter | C1: OBS_VALUE
A2: 42825 | B2: 2017Q1 | C2: -0.6
A3: 42916 | B3: 2017Q2 | C3: -0.6
A4: 43008 | B4: 2017Q3 | C4: -0.8
A5: 43100 | B5: 2017Q4 | C5: -1.4
A6: 43190 | B6: 2018Q1 | C6: 2.9
A7: 43281 | B7: 2018Q2 | C7: 2.3
A8: 43373 | B8: 2018Q3 | C8: 2.2
A9: 43465 | B9: 2018Q4 | C9: 2.5
A10: 43555 | B10: 2019Q1 | C10: -2.1
A11: 43646 | B11: 2019Q2 | C11: -1.6
A12: 43738 | B12: 2019Q3 | C12: -1.1
A13: 43830 | B13: 2019Q4 | C13: 0
... A37: 46022 | B37: 2025Q4 | C37: 1.9

Sheet Model
A1: Date | B1: GDP | C1: Oil_Rev | D1: Non_Oil_Rev | E1: GovEx | F1: CAPEX | G1: PMI | H1: POS | I1: Oil_Price | J1: Oil_Production | K1: M3 | L1: Exports
A2: {=_xlfn._xlws.FILTER(GDP_By_Main_Economic_Activity!A2:A1000, GDP_By_Main_Economic_Activity!A2:A1000<>"")} -> 42825 | B2: {=_xlfn._xlws.FILTER(GDP_By_Main_Economic_Activity[Gross Domestic Product], GDP_By_Main_Economic_Activity[Gross Domestic Product]<>"")} -> 932702 | C2: {=_xlfn._xlws.FILTER(Government_Revenues[Oil Revenue], Government_Revenues[Oil Revenue]<>"")} -> 115100 | D2: {=_xlfn._xlws.FILTER(Government_Revenues[Non Oil Revenues], Government_Revenues[Non Oil Revenues]<>"")} -> 29000 | E2: {=_xlfn._xlws.FILTER(Government_Expenditures[Total Exp], Government_Expenditures[Total Exp]<>"")} -> 170300 | F2: {=_xlfn._xlws.FILTER(Government_Expenditures[CAPEX], Government_Expenditures[CAPEX]<>"")} -> 9300 | G2: {=_xlfn._xlws.FILTER(PMI_Quarterly[PMI], PMI_Quarterly[PMI]<>"")} -> 56.7 | H2: {=_xlfn._xlws.FILTER(POS_Quarterly[Value], POS_Quarterly[Value]<>"")} -> 15358633 | I2: {=_xlfn._xlws.FILTER(Crude_Oil_Quarterly[Price], Crude_Oil_Quarterly[Price]<>"")} -> 53.883333 | J2: {=_xlfn._xlws.FILTER(Crude_Oil_Quarterly[Production], Crude_Oil_Quarterly[Production]<>"")} -> 9898 | K2: {=_xlfn._xlws.FILTER(M3_Quarterly[M3], M3_Quarterly[M3]<>"")} -> 1779430.4 | L2: {=(_xlfn._xlws.FILTER(balance_of_payments!B30:B500, (balance_of_payments!C30:C500<>"") * (balance_of_payments!B30:B500<>"")))/1000} -> 207398.77
A3: 42916 | B3: 922635 | C3: 101000 | D3: 62900 | E3: 210400 | F3: 34700 | G3: 55.4 | H3: 17061200 | I3: 50.1 | J3: 9948 | K3: 1803423 | L3: 189753.39
A4: 43008 | B4: 933711 | C4: 94300 | D4: 47800 | E4: 190900 | F4: 24500 | G4: 55.7 | H4: 16125500 | I4: 52.11 | J4: 10005 | K4: 1804225.9 | L4: 196313
A5: 43100 | B5: 985165 | C5: 129500 | D5: 112000 | E5: 356400 | F5: 101000 | G5: 56.8 | H5: 17518700 | I5: 61.53 | J5: 9992.6667 | K5: 1790167.3 | L5: 238516
A6: 43190 | B6: 958113 | C6: 113900 | D6: 52400 | E6: 200600 | F6: 25300 | G6: 53 | H6: 18472100 | I6: 66.806667 | J6: 9955.3333 | K6: 1802989.5 | L6: 244247
A7: 43281 | B7: 958245 | C7: 184200 | D7: 89400 | E7: 281000 | F7: 53900 | G7: 53.8 | H7: 20163900 | I7: 74.383333 | J7: 10116.333 | K7: 1802537.1 | L7: 281109
A8: 43373 | B8: 962710 | C8: 154000 | D8: 69300 | E8: 230500 | F8: 46300 | G8: 54.8 | H8: 20220500 | I8: 75.24 | J8: 10437 | K8: 1815545.4 | L8: 288445
A9: 43465 | B9: 1016937 | C9: 158000 | D9: 94000 | E9: 318000 | F9: 70000 | G9: 55.9 | H9: 21362167 | I9: 67.906667 | J9: 10757 | K9: 1829630.8 | L9: 290151
A10: 43555 | B10: 985357 | C10: 169100 | D10: 76300 | E10: 217600 | F10: 21700 | G10: 56.5 | H10: 23405433 | I10: 63.196667 | J10: 10055.667 | K10: 1829866.9 | L10: 249100.28
A11: 43646 | B11: 974442 | C11: 174400 | D11: 86300 | E11: 267200 | F11: 48800 | G11: 57.2 | H11: 25805533 | I11: 68.543333 | J11: 9731.3333 | K11: 1871915.9 | L11: 252631.01
A12: 43738 | B12: 976512 | C12: 131800 | D12: 62100 | E12: 203600 | F12: 18600 | G12: 57 | H12: 25850400 | I12: 62.083333 | J12: 9528 | K12: 1885259 | L12: 235886.73
A13: 43830 | B13: 1024040 | C13: 118800 | D13: 120300 | E13: 371400 | F13: 82700 | G13: 57.7 | H13: 27472033 | I13: 63.41 | J13: 9824 | K13: 1934567.8 | L13: 243446.35
A14: 43921 | B14: 972107 | C14: 128800 | D14: 63300 | E14: 226200 | F14: 20700 | G14: 49.9 | H14: 28162133 | I14: 50.44 | J14: 9733.3333 | K14: 1975413.5 | L14: 191685
... A37: 46022 | B37: 1272528 | C37: 154185 | D37: 122558 | E37: 371589.13 | F37: 27785.705 | G37: 58.7 | H37: 69266667 | I37: 59.196667 | J37: 9716.6667 | K37: 3148267.1 | L37: 300397.07
A38: 46053 | B38: =B37*(1+AVERAGE((B34-B33)/B33,(B35-B34)/B34,(B36-B35)/B35,(B37-B36)/B36)) -> 1288466 | F38: 28086.515 | G38: 56.2 | H38: 63770236 | I38: 74.153333 | J38: 10098.667 | K38: 3297055.4

Sheet Nowcasting
B2: Scenario Analysis
B3: Label | C3: Value (Base Case)
B4: POS Growth % | C4: =((Model!H38-Model!H37)/Model!H37) -> -0.079351747
B5: Oil Prod (mb/d) | C5: =Model!J38/1000 -> 10.098667
B6: PMI Index | C6: =Model!G38 -> 56.2
B8: Nowcasting GDP
B9: Thousands SAR | C9: =Model!B38 -> 1288466
B10: YoY Growth Rate | C10: =(Model!B38-Model!B34)/Model!B34 -> 0.06748578
B11: QoQ Growth Rate | C11: =(Model!B38-Model!B37)/Model!B37 -> 0.012524684
B14: Nowcasting Government Performance
B15: Revenues | C15: =Model!C38+Model!D38 -> 0
B16: Expenditures | C16: =Model!E38 -> 0
B17: Deficit/Surplus | C17: =C15-C16 -> 0

Sheet GDP_By_Kind_of_Economic_Activit
A1: Date | B1: Quarter | C1: Quarter2 | D1: Agriculture | E1: Mining & Quarrying | F1: Crude Petroleum & Natural Gas | G1: Other Mining & Quarrying | H1: Manufacturing | I1: Petroleum Refining | J1: Energy | K1: Construction | L1: Trade | M1: Transport, Storage & Communication | N1: Finance, Insurance, Real Estate & Business Services | O1: Real Estate | P1: Finance , Insurance and Business services | Q1: Community, Social & Personal Services | R1: Government Activities
A2: 42825 | B2: 2017Q1 | C2: 2017 Q1 | D2: 24373 | E2: 266363 | F2: 262285 | G2: 3936 | H2: 146699 | I2: 61846 | J2: 5988 | K2: 51412 | L2: 86822 | M2: 49184 | N2: 93203 | O2: 51858 | P2: 40845 | Q2: 24997 | R2: 141861
A3: 42916 | B3: 2017Q2 | C3: 2017 Q2 | D3: 26197 | E3: 267970 | F3: 264429 | G3: 3644 | H3: 149510 | I3: 65603 | J3: 16120 | K3: 49324 | L3: 81924 | M3: 47480 | N3: 92784 | O3: 51137 | P3: 41218 | Q3: 24718 | R3: 129052
A4: 43008 | B4: 2017Q3 | C4: 2017 Q3 | D4: 27068 | E4: 271465 | F4: 267701 | G4: 3790 | H4: 146310 | I4: 67975 | J4: 24018 | K4: 53923 | L4: 89668 | M4: 45764 | N4: 91896 | O4: 49976 | P4: 41592 | Q4: 24175 | R4: 122371
A5: 43100 | B5: 2017Q4 | C5: 2017 Q4 | D5: 21843 | E5: 268215 | F5: 265262 | G5: 3314 | H5: 143413 | I5: 67040 | J5: 10163 | K5: 56069 | L5: 94104 | M5: 51986 | N5: 100527 | O5: 51945 | P5: 48608 | Q5: 24824 | R5: 160031
A6: 43190 | B6: 2018Q1 | C6: 2018 Q1 | D6: 24989 | E6: 268144 | F6: 263823 | G6: 4191 | H6: 147687 | I6: 61149 | J6: 5918 | K6: 54035 | L6: 89507 | M6: 50453 | N6: 96697 | O6: 53612 | P6: 42608 | Q6: 26722 | R6: 148584
A7: 43281 | B7: 2018Q2 | C7: 2018 Q2 | D7: 26998 | E7: 272436 | F7: 268762 | G7: 3751 | H7: 150671 | I7: 62892 | J7: 15631 | K7: 52794 | L7: 84824 | M7: 47951 | N7: 97795 | O7: 52575 | P7: 44952 | Q7: 26944 | R7: 139218
A8: 43373 | B8: 2018Q3 | C8: 2018 Q3 | D8: 27499 | E8: 282727 | F8: 279007 | G8: 3827 | H8: 146694 | I8: 65839 | J8: 23784 | K8: 57023 | L8: 92377 | M8: 47387 | N8: 95715 | O8: 51161 | P8: 44329 | Q8: 25862 | R8: 123729
A9: 43465 | B9: 2018Q4 | C9: 2018 Q4 | D9: 22295 | E9: 289811 | F9: 286801 | G9: 3355 | H9: 144364 | I9: 64088 | J9: 9405 | K9: 56723 | L9: 95296 | M9: 53514 | N9: 105380 | O9: 53176 | P9: 52366 | Q9: 26436 | R9: 163205
A10: 43555 | B10: 2019Q1 | C10: 2019 Q1 | D10: 25095 | E10: 269820 | F10: 265402 | G10: 4521 | H10: 152930 | I10: 62353 | J10: 6469 | K10: 57313 | L10: 91754 | M10: 54908 | N10: 101889 | O10: 55470 | P10: 46096 | Q10: 27917 | R10: 150640
A11: 43646 | B11: 2019Q2 | C11: 2019 Q2 | D11: 27061 | E11: 263628 | F11: 259742 | G11: 3983 | H11: 153371 | I11: 60802 | J11: 15620 | K11: 55464 | L11: 88592 | M11: 52472 | N11: 102576 | O11: 52796 | P11: 49736 | Q11: 28318 | R11: 140746
A12: 43738 | B12: 2019Q3 | C12: 2019 Q3 | D12: 27730 | E12: 263963 | F12: 259805 | G12: 4257 | H12: 149921 | I12: 62121 | J12: 24089 | K12: 57471 | L12: 98425 | M12: 50358 | N12: 100409 | O12: 51754 | P12: 48605 | Q12: 27738 | R12: 129495
A13: 43830 | B13: 2019Q4 | C13: 2019 Q4 | D13: 22623 | E13: 272036 | F13: 268434 | G13: 3699 | H13: 149693 | I13: 61823 | J13: 9924 | K13: 56891 | L13: 104451 | M13: 54495 | N13: 109234 | O13: 54199 | P13: 55175 | Q13: 28647 | R13: 163790
... A28: 45199 | B28: 2023Q3 | C28: 2023 Q3 | D28: 29989 | E28: 249901 | F28: 245412 | G28: 4510 | H28: 175385 | I28: 63572 | J28: 28077 | K28: 86301 | L28: 123528 | M28: 59255 | N28: 130109 | O28: 57076 | P28: 72954 | Q28: 39440 | R28: 142784
A29: 45291 | B29: 2023Q4 | C29: 2023 Q4 | D29: 27130 | E29: 244863 | F29: 240635 | G29: 4201 | H29: 171123 | I29: 58639 | J29: 11486 | K29: 89192 | L29: 131830 | M29: 69288 | N29: 135638 | O29: 58967 | P29: 76575 | Q29: 41177 | R29: 175848 | AD29: Community, Social & Personal Services
A30: 45382 | B30: 2024Q1 | C30: 2024 Q1 | D30: 29044 | E30: 242861 | F30: 237303 | G30: 5557 | H30: 193656 | I30: 61734 | J30: 7741 | K30: 85653 | L30: 133198 | M30: 66280 | N30: 130233 | O30: 62323 | P30: 67910 | Q30: 46123 | R30: 168528
A31: 45473 | B31: 2024Q2 | C31: 2024 Q2 | D31: 29410 | E31: 242780 | F31: 237728 | G31: 5053 | H31: 201056 | I31: 67912 | J31: 18707 | K31: 83611 | L31: 132286 | M31: 60883 | N31: 132206 | O31: 61565 | P31: 70641 | Q31: 41764 | R31: 145185
A32: 45565 | B32: 2024Q3 | C32: 2024 Q3 | D32: 31598 | E32: 250222 | F32: 245430 | G32: 4792 | H32: 181005 | I32: 63083 | J32: 29115 | K32: 91189 | L32: 129962 | M32: 61683 | N32: 139094 | O32: 58642 | P32: 80451 | Q32: 41350 | R32: 148589
A33: 45657 | B33: 2024Q4 | C33: 2024 Q4 | D33: 27936 | E33: 246777 | F33: 242150 | G33: 4627 | H33: 186741 | I33: 67614 | J33: 12495 | K33: 94830 | L33: 140402 | M33: 72207 | N33: 143331 | O33: 60639 | P33: 82692 | Q33: 43322 | R33: 180185
A34: 45747 | B34: 2025Q1 | C34: 2025 Q1 | D34: 30014 | E34: 239397 | F34: 233689 | G34: 5664 | H34: 202640 | I34: 64058 | J34: 7892 | K34: 89217 | L34: 143536 | M34: 70380 | N34: 138297 | O34: 64856 | P34: 73230 | Q34: 48332 | R34: 173860
A35: 45838 | B35: 2025Q2 | C35: 2025 Q2 | D35: 30729 | E35: 252871 | F35: 247711 | G35: 5160 | H35: 209286 | I35: 69731 | J35: 20634 | K35: 88102 | L35: 140881 | M35: 63235 | N35: 140772 | O35: 63844 | P35: 76860 | Q35: 43757 | R35: 145865
A36: 45930 | B36: 2025Q3 | C36: 2025 Q3 | D36: 31851 | E36: 268336 | F36: 263401 | G36: 4963 | H36: 193740 | I36: 70613 | J36: 30980 | K36: 93768 | L36: 136675 | M36: 63680 | N36: 144685 | O36: 61186 | P36: 83727 | Q36: 43381 | R36: 150604
A37: 46022 | B37: 2025Q4 | C37: 2025 Q4 | D37: 28965 | E37: 276952 | F37: 272237 | G37: 4764 | H37: 195753 | I37: 71000 | J37: 12607 | K37: 98592 | L37: 147972 | M37: 74572 | N37: 148960 | O37: 62800 | P37: 86408 | Q37: 45166 | R37: 178064
AD38: Agriculture
AD39: Mining & Quarrying
AD40: Crude Petroleum & Natural Gas
AD41: Other Mining & Quarrying
AD42: Manufacturing
AD43: Petroleum Refining
AD44: Energy
AD45: Construction
AD46: Trade
AD47: Transport, Storage & Communication
AD48: Finance, Insurance, Real Estate & Business Services
AD49: Real Estate
... AD52: Government Activities

Sheet Data
B3: GDP By Kind of economic activities
B4: {=GDP_By_Kind_of_Economic_Activities[#All]} -> Date | C4: Quarter | D4: Quarter2 | E4: Agriculture | F4: Mining & Quarrying | G4: Crude Petroleum & Natural Gas | H4: Other Mining & Quarrying | I4: Manufacturing | J4: Petroleum Refining | K4: Energy | L4: Construction | M4: Trade | N4: Transport, Storage & Communication | O4: Finance, Insurance, Real Estate & Business Services | P4: Real Estate | Q4: Finance , Insurance and Business services | R4: Community, Social & Personal Services | S4: Government Activities | U4: Non Sorted | Z4: Sorted
B5: 42825 | C5: 2017Q1 | D5: 2017 Q1 | E5: 24373 | F5: 266363 | G5: 262285 | H5: 3936 | I5: 146699 | J5: 61846 | K5: 5988 | L5: 51412 | M5: 86822 | N5: 49184 | O5: 93203 | P5: 51858 | Q5: 40845 | R5: 24997 | S5: 141861 | U5: Agriculture | V5: {=TRANSPOSE(_xlfn.XLOOKUP(Dashboard!$A$1,$C$5:$C$40,$E$5:$S$40))} -> 26563 | Z5: {=_xlfn.SORTBY($U$5:$U$19,_xlfn.ANCHORARRAY($V$5),1)} -> Other Mining & Quarrying | AA5: {=_xlfn.XLOOKUP(_xlfn.ANCHORARRAY(Z5),$U$5:$U19,_xlfn.ANCHORARRAY(V5))} -> 4228
B6: 42916 | C6: 2017Q2 | D6: 2017 Q2 | E6: 26197 | F6: 267970 | G6: 264429 | H6: 3644 | I6: 149510 | J6: 65603 | K6: 16120 | L6: 49324 | M6: 81924 | N6: 47480 | O6: 92784 | P6: 51137 | Q6: 41218 | R6: 24718 | S6: 129052 | U6: Mining & Quarrying | V6: 231540 | Z6: Energy | AA6: 15595
B7: 43008 | C7: 2017Q3 | D7: 2017 Q3 | E7: 27068 | F7: 271465 | G7: 267701 | H7: 3790 | I7: 146310 | J7: 67975 | K7: 24018 | L7: 53923 | M7: 89668 | N7: 45764 | O7: 91896 | P7: 49976 | Q7: 41592 | R7: 24175 | S7: 122371 | U7: Crude Petroleum & Natural Gas | V7: 227047 | Z7: Agriculture | AA7: 26563
B8: 43100 | C8: 2017Q4 | D8: 2017 Q4 | E8: 21843 | F8: 268215 | G8: 265262 | H8: 3314 | I8: 143413 | J8: 67040 | K8: 10163 | L8: 56069 | M8: 94104 | N8: 51986 | O8: 100527 | P8: 51945 | Q8: 48608 | R8: 24824 | S8: 160031 | U8: Other Mining & Quarrying | V8: 4228 | Z8: Community, Social & Personal Services | AA8: 31705
B9: 43190 | C9: 2018Q1 | D9: 2018 Q1 | E9: 24989 | F9: 268144 | G9: 263823 | H9: 4191 | I9: 147687 | J9: 61149 | K9: 5918 | L9: 54035 | M9: 89507 | N9: 50453 | O9: 96697 | P9: 53612 | Q9: 42608 | R9: 26722 | S9: 148584 | U9: Manufacturing | V9: 162927 | Z9: Transport, Storage & Communication | AA9: 47259
B10: 43281 | C10: 2018Q2 | D10: 2018 Q2 | E10: 26998 | F10: 272436 | G10: 268762 | H10: 3751 | I10: 150671 | J10: 62892 | K10: 15631 | L10: 52794 | M10: 84824 | N10: 47951 | O10: 97795 | P10: 52575 | Q10: 44952 | R10: 26944 | S10: 139218 | U10: Petroleum Refining | V10: 57893 | Z10: Construction | AA10: 51825
B11: 43373 | C11: 2018Q3 | D11: 2018 Q3 | E11: 27499 | F11: 282727 | G11: 279007 | H11: 3827 | I11: 146694 | J11: 65839 | K11: 23784 | L11: 57023 | M11: 92377 | N11: 47387 | O11: 95715 | P11: 51161 | Q11: 44329 | R11: 25862 | S11: 123729 | U11: Energy | V11: 15595 | Z11: Finance , Insurance and Business services | AA11: 52717
B12: 43465 | C12: 2018Q4 | D12: 2018 Q4 | E12: 22295 | F12: 289811 | G12: 286801 | H12: 3355 | I12: 144364 | J12: 64088 | K12: 9405 | L12: 56723 | M12: 95296 | N12: 53514 | O12: 105380 | P12: 53176 | Q12: 52366 | R12: 26436 | S12: 163205 | U12: Construction | V12: 51825 | Z12: Real Estate | AA12: 56531
B13: 43555 | C13: 2019Q1 | D13: 2019 Q1 | E13: 25095 | F13: 269820 | G13: 265402 | H13: 4521 | I13: 152930 | J13: 62353 | K13: 6469 | L13: 57313 | M13: 91754 | N13: 54908 | O13: 101889 | P13: 55470 | Q13: 46096 | R13: 27917 | S13: 150640 | U13: Trade | V13: 101440 | Z13: Petroleum Refining | AA13: 57893
B14: 43646 | C14: 2019Q2 | D14: 2019 Q2 | E14: 27061 | F14: 263628 | G14: 259742 | H14: 3983 | I14: 153371 | J14: 60802 | K14: 15620 | L14: 55464 | M14: 88592 | N14: 52472 | O14: 102576 | P14: 52796 | Q14: 49736 | R14: 28318 | S14: 140746 | U14: Transport, Storage & Communication | V14: 47259 | Z14: Trade | AA14: 101440
B15: 43738 | C15: 2019Q3 | D15: 2019 Q3 | E15: 27730 | F15: 263963 | G15: 259805 | H15: 4257 | I15: 149921 | J15: 62121 | K15: 24089 | L15: 57471 | M15: 98425 | N15: 50358 | O15: 100409 | P15: 51754 | Q15: 48605 | R15: 27738 | S15: 129495 | U15: Finance, Insurance, Real Estate & Business Services | V15: 109332 | Z15: Finance, Insurance, Real Estate & Business Services | AA15: 109332
B16: 43830 | C16: 2019Q4 | D16: 2019 Q4 | E16: 22623 | F16: 272036 | G16: 268434 | H16: 3699 | I16: 149693 | J16: 61823 | K16: 9924 | L16: 56891 | M16: 104451 | N16: 54495 | O16: 109234 | P16: 54199 | Q16: 55175 | R16: 28647 | S16: 163790 | U16: Real Estate | V16: 56531 | Z16: Government Activities | AA16: 133593
B17: 43921 | C17: 2020Q1 | D17: 2020 Q1 | E17: 25183 | F17: 262656 | G17: 257787 | H17: 4858 | I17: 142871 | J17: 47357 | K17: 6422 | L17: 55026 | M17: 94482 | N17: 51693 | O17: 102946 | P17: 55233 | Q17: 47517 | R17: 30641 | S17: 151274 | U17: Finance , Insurance and Business services | V17: 52717 | Z17: Manufacturing | AA17: 162927
... B19: 44104 | C19: 2020Q3 | D19: 2020 Q3 | E19: 29109 | F19: 245302 | G19: 240924 | H19: 4387 | I19: 141839 | J19: 50762 | K19: 24547 | L19: 53839 | M19: 93871 | N19: 44233 | O19: 101573 | P19: 53414 | Q19: 48035 | R19: 29524 | S19: 130398 | U19: Government Activities | V19: 133593 | Z19: Mining & Quarrying | AA19: 231540
B20: 44196 | C20: 2020Q4 | D20: 2020 Q4 | E20: 23276 | F20: 246275 | G20: 242630 | H20: 3743 | I20: 154115 | J20: 63710 | K20: 10230 | L20: 54852 | M20: 102714 | N20: 48294 | O20: 111295 | P20: 56058 | Q20: 55259 | R20: 29649 | S20: 161578
B21: 44286 | C21: 2021Q1 | D21: 2021 Q1 | E21: 25797 | F21: 227405 | G21: 221467 | H21: 4945 | I21: 163695 | J21: 57617 | K21: 6467 | L21: 55678 | M21: 102023 | N21: 50172 | O21: 107613 | P21: 58196 | Q21: 49236 | R21: 34990 | S21: 154050
B22: 44377 | C22: 2021Q2 | D22: 2021 Q2 | E22: 26563 | F22: 231540 | G22: 227047 | H22: 4228 | I22: 162927 | J22: 57893 | K22: 15595 | L22: 51825 | M22: 101440 | N22: 47259 | O22: 109332 | P22: 56531 | Q22: 52717 | R22: 31705 | S22: 133593
B23: 44469 | C23: 2021Q3 | D23: 2021 Q3 | E23: 29172 | F23: 265611 | G23: 261402 | H23: 4360 | I23: 155648 | J23: 60496 | K23: 25400 | L23: 60568 | M23: 103750 | N23: 50971 | O23: 112024 | P23: 54678 | Q23: 57386 | R23: 32645 | S23: 134952
B24: 44561 | C24: 2021Q4 | D24: 2021 Q4 | E24: 24016 | F24: 271201 | G24: 267749 | H24: 4013 | I24: 169670 | J24: 73790 | K24: 10872 | L24: 66188 | M24: 108109 | N24: 59117 | O24: 117658 | P24: 56631 | Q24: 61099 | R24: 33421 | S24: 165139
B25: 44651 | C25: 2022Q1 | D25: 2022 Q1 | E25: 26322 | F25: 272147 | G25: 267209 | H25: 4788 | I25: 181483 | J25: 67608 | K25: 6738 | L25: 72122 | M25: 108808 | N25: 57830 | O25: 114763 | P25: 58597 | Q25: 56114 | R25: 36285 | S25: 160997
B26: 44742 | C26: 2022Q2 | D26: 2022 Q2 | E26: 26937 | F26: 284996 | G26: 280413 | H26: 4441 | I26: 185672 | J26: 67487 | K26: 16344 | L26: 74637 | M26: 111150 | N26: 53613 | O26: 116436 | P26: 57828 | Q26: 58595 | R26: 35350 | S26: 139528
B27: 44834 | C27: 2022Q3 | D27: 2022 Q3 | E27: 29479 | F27: 304732 | G27: 300128 | H27: 4459 | I27: 176218 | J27: 65173 | K27: 27411 | L27: 82441 | M27: 115746 | N27: 55415 | O27: 121846 | P27: 55870 | Q27: 66073 | R27: 35668 | S27: 141144
B28: 44926 | C28: 2022Q4 | D28: 2022 Q4 | E28: 24663 | F28: 291393 | G28: 287134 | H28: 4124 | I28: 181331 | J28: 70335 | K28: 11138 | L28: 85489 | M28: 121323 | N28: 66232 | O28: 129150 | P28: 57928 | Q28: 71355 | R28: 37788 | S28: 173352
B29: 45016 | C29: 2023Q1 | D29: 2023 Q1 | E29: 27418 | F29: 278334 | G29: 273288 | H29: 5082 | I29: 186332 | J29: 62483 | K29: 7297 | L29: 83286 | M29: 123923 | N29: 63424 | O29: 121137 | P29: 60420 | Q29: 60822 | R29: 42150 | S29: 164264
B30: 45107 | C30: 2023Q2 | D30: 2023 Q2 | E30: 27771 | F30: 274028 | G30: 269291 | H30: 4707 | I30: 193360 | J30: 66014 | K30: 16955 | L30: 79495 | M30: 122334 | N30: 58267 | O30: 121725 | P30: 59268 | Q30: 62526 | R30: 40168 | S30: 138876
B31: 45199 | C31: 2023Q3 | D31: 2023 Q3 | E31: 29989 | F31: 249901 | G31: 245412 | H31: 4510 | I31: 175385 | J31: 63572 | K31: 28077 | L31: 86301 | M31: 123528 | N31: 59255 | O31: 130109 | P31: 57076 | Q31: 72954 | R31: 39440 | S31: 142784
... B40: 46022 | C40: 2025Q4 | D40: 2025 Q4 | E40: 28965 | F40: 276952 | G40: 272237 | H40: 4764 | I40: 195753 | J40: 71000 | K40: 12607 | L40: 98592 | M40: 147972 | N40: 74572 | O40: 148960 | P40: 62800 | Q40: 86408 | R40: 45166 | S40: 178064
B50: GDP By Main Economics Activity
B51: {=GDP_By_Main_Economic_Activity[#All]} -> Date | C51: Quarter | D51: Oil Activities | E51: Non-Oil Activities | F51: Government Activities | G51: Gross Value Added | H51: Net Taxes on Products | I51: Gross Domestic Product | L51: Oil Activities | M51: Non-Oil Activities | U51: Non Sorted | Z51: Sorted
B52: 42825 | C52: 2017Q1 | D52: 323387 | E52: 427664 | F52: 141861 | G52: 889235 | H52: 41728 | I52: 932702 | L52: =_xlfn.XLOOKUP(Dashboard!$A$1,Data!$C$52:$C$87,Data!$D$52:$D$87) -> 284060 | M52: =_xlfn.XLOOKUP(Dashboard!$A$1,Data!$C$52:$C$87,Data!$E$52:$E$87) -> 490817 | U52: Oil Activities | V52: =_xlfn.XLOOKUP(Dashboard!$A$1,Data!$C$52:$C$87,Data!$D$52:$D$87) -> 284060 | Z52: {=_xlfn.SORTBY($U$52:$U$57,$V$52:$V$57,-1)} -> GDP | AA52: {=_xlfn.XLOOKUP(_xlfn.ANCHORARRAY($Z$52),$U$52:$U$57,$V$52:$V$57)} -> 965383
B53: 42916 | C53: 2017Q2 | D53: 327933 | E53: 429552 | F53: 129052 | G53: 878557 | H53: 46796 | I53: 922635 | U53: Non-Oil Activities | V53: =_xlfn.XLOOKUP(Dashboard!$A$1,Data!$C$52:$C$87,Data!$E$52:$E$87) -> 490817 | Z53: GVA | AA53: 918391
B54: 43008 | C54: 2017Q3 | D54: 332904 | E54: 443768 | F54: 122371 | G54: 890649 | H54: 39464 | I54: 933711 | U54: Government Activities | V54: =_xlfn.XLOOKUP(Dashboard!$A$1,Data!$C$52:$C$87,Data!$F$52:$F$87) -> 133593 | Z54: Non-Oil Activities | AA54: 490817
B55: 43100 | C55: 2017Q4 | D55: 329685 | E55: 447054 | F55: 160031 | G55: 938914 | H55: 45812 | I55: 985165 | U55: GVA | V55: =_xlfn.XLOOKUP(Dashboard!$A$1,Data!$C$52:$C$87,Data!$G$52:$G$87) -> 918391 | Z55: Oil Activities | AA55: 284060
B56: 43190 | C56: 2018Q1 | D56: 324708 | E56: 441322 | F56: 148584 | G56: 913445 | H56: 42822 | I56: 958113 | U56: Net Taxes of Products | V56: =_xlfn.XLOOKUP(Dashboard!$A$1,Data!$C$52:$C$87,Data!$H$52:$H$87) -> 47040 | Z56: Government Activities | AA56: 133593
B57: 43281 | C57: 2018Q2 | D57: 331130 | E57: 446211 | F57: 139218 | G57: 912852 | H57: 46922 | I57: 958245 | U57: GDP | V57: =_xlfn.XLOOKUP(Dashboard!$A$1,Data!$C$52:$C$87,Data!$I$52:$I$87) -> 965383 | Z57: Net Taxes of Products | AA57: 47040
B58: 43373 | C58: 2018Q3 | D58: 344068 | E58: 458359 | F58: 123729 | G58: 918207 | H58: 40861 | I58: 962710
B59: 43465 | C59: 2018Q4 | D59: 351618 | E59: 458356 | F59: 163205 | G59: 969385 | H59: 46254 | I59: 1016937
B60: 43555 | C60: 2019Q1 | D60: 327142 | E60: 461734 | F60: 150640 | G60: 937130 | H60: 48676 | I60: 985357
...

Sheet GrossDomesticProduct
A1: Value
A2: 816113
A3: 815279
A4: 816590
A5: 824518
A6: 819438
A7: 831118
A8: 850723
A9: 867617
A10: 876230
A11: 866234
A12: 871065
A13: 890954
... A57: 1272528

Sheet Dashboard
A1: =CONCATENATE(D5,LEFT(D6,1),RIGHT(D6,1)) -> 2021Q2
C4: Time Period
B5: Year | D5: 2021
B6: Quarter | D6: Quarter 2
C9: Gross Doemstic Product | E9: Government Revenues | G9: Government Expenditures | I9: Deficit/Surplus | K9: Exports | M9: Imports | O9: Trade Balance
C10: =_xlfn.XLOOKUP($A$1,Data!$C$52:$C$87,Data!$I$52:$I$87) -> 965383 | E10: =_xlfn.XLOOKUP(Dashboard!$A$1,Data!$C$95:$C$130,Data!$D$95:$D$130) -> 248100 | G10: =_xlfn.XLOOKUP(Dashboard!$A$1,Data!$C$137:$C$172,Data!$D$137:$D$172) -> 252700 | I10: =_xlfn.XLOOKUP(Dashboard!$A$1,Data!$C$180:$C$215,Data!$D$180:$D$215) -> -4600 | K10: =_xlfn.XLOOKUP($A$1,Data!$C$223:$C$258,Data!$D$223:$D$258) -> 232179 | M10: =_xlfn.XLOOKUP($A$1,Data!$C$223:$C$258,Data!$E$223:$E$258) -> 140424 | O10: =_xlfn.XLOOKUP($A$1,Data!$C$223:$C$258,Data!$G$223:$G$258) -> 91755
